<?xml version="1.0" encoding="utf-8"?>
<!-- This URDF was automatically created by SolidWorks to URDF Exporter! Originally created by Stephen Brawner (brawner@gmail.com) 
     Commit Version: 1.6.0-4-g7f85cfe  Build Version: 1.6.7995.38578
     For more information, please see http://wiki.ros.org/sw_urdf_exporter -->
<robot
  name="kanuopu-robot">
  
  <mujoco>

    <compiler

    meshdir="meshes/"

    balanceinertia="false"

    discardvisual="false" />

  </mujoco>
  
  <link
    name="BASE_S">
    <inertial>
              <origin 
                xyz="-0.003777 -1.7e-05 -0.06481" 
                rpy="0 0 0" />
              <mass 
                value="62.471319" />
              <inertia
                ixx="2.446972152229"
                ixy="-9.1400898e-05"
                ixz="0.029491874943999997"
                iyy="2.407903556503"
                iyz="0.000335406891"
                izz="1.689936785554" />
            </inertial>
    <visual>
      <origin
        xyz="0 0 0"
        rpy="0 0 0" />
      <geometry>
        <mesh
          filename="package://kanuopu-robot/meshes/BASE_S.STL" />
      </geometry>
      <material
        name="">
        <color
          rgba="0.792156862745098 0.819607843137255 0.933333333333333 1" />
      </material>
    </visual>
    <collision>
      <origin
        xyz="0 0 0"
        rpy="0 0 0" />
      <geometry>
        <mesh
          filename="package://kanuopu-robot/meshes/BASE_S.STL" />
      </geometry>
    </collision>
  </link>
  <link
    name="UP-DOWN_S">
    <inertial>
              <origin 
                xyz="-0.041989 2.9999999999999997e-05 0.321005" 
                rpy="0 0 0" />
              <mass 
                value="5.061434" />
              <inertia
                ixx="0.10835080298800001"
                ixy="6.6975100000000005e-06"
                ixz="0.025547207914"
                iyy="0.117288930706"
                iyz="3.8899630000000005e-06"
                izz="0.0196810695" />
            </inertial>
    <visual>
      <origin
        xyz="0 0 0"
        rpy="0 0 0" />
      <geometry>
        <mesh
          filename="package://kanuopu-robot/meshes/UP-DOWN_S.STL" />
      </geometry>
      <material
        name="">
        <color
          rgba="0.792156862745098 0.819607843137255 0.933333333333333 1" />
      </material>
    </visual>
    <collision>
      <origin
        xyz="0 0 0"
        rpy="0 0 0" />
      <geometry>
        <mesh
          filename="package://kanuopu-robot/meshes/UP-DOWN_S.STL" />
      </geometry>
    </collision>
  </link>
  <joint
    name="UP-DOWN"
    type="prismatic">
    <origin
      xyz="8.8652E-05 0 0.1005"
      rpy="0 0 0" />
    <parent
      link="BASE_S" />
    <child
      link="UP-DOWN_S" />
    <axis
      xyz="0 0 1" />
    <limit
      lower="0"
      upper="0.225"
      effort="19.8"
      velocity="0.0226" />
  </joint>
  <link
    name="WAIST_R_S">
    <inertial>
              <origin 
                xyz="0.049284 6.8e-05 0.00412" 
                rpy="0 0 0" />
              <mass 
                value="1.551026" />
              <inertia
                ixx="0.001275813984"
                ixy="-2.1471619999999998e-06"
                ixz="-3.114039e-05"
                iyy="0.0014353835430000001"
                iyz="4.805574e-06"
                izz="0.00099114161" />
            </inertial>
    <visual>
      <origin
        xyz="0 0 0"
        rpy="0 0 0" />
      <geometry>
        <mesh
          filename="package://kanuopu-robot/meshes/WAIST_R_S.STL" />
      </geometry>
      <material
        name="">
        <color
          rgba="0.776470588235294 0.756862745098039 0.737254901960784 1" />
      </material>
    </visual>
    <collision>
      <origin
        xyz="0 0 0"
        rpy="0 0 0" />
      <geometry>
        <mesh
          filename="package://kanuopu-robot/meshes/WAIST_R_S.STL" />
      </geometry>
    </collision>
  </link>
  <joint
    name="WAIST_R"
    type="revolute">
    <origin
      xyz="-0.0653 0 0.469"
      rpy="0 0 0" />
    <parent
      link="UP-DOWN_S" />
    <child
      link="WAIST_R_S" />
    <axis
      xyz="1 0 0" />
    <limit
      lower="-0.34907"
      upper="0.43633"
      effort="32"
      velocity="6.39" />
  </joint>
  <link
    name="WAIST_Y_S">
    <inertial>
              <origin 
                xyz="1.7e-05 0.006685 0.051405" 
                rpy="0 0 0" />
              <mass 
                value="1.616508" />
              <inertia
                ixx="0.001556987289"
                ixy="1.202979e-06"
                ixz="-2.308716e-06"
                iyy="0.001095523444"
                iyz="-3.8896874000000006e-05"
                izz="0.00138311366" />
            </inertial>
    <visual>
      <origin
        xyz="0 0 0"
        rpy="0 0 0" />
      <geometry>
        <mesh
          filename="package://kanuopu-robot/meshes/WAIST_Y_S.STL" />
      </geometry>
      <material
        name="">
        <color
          rgba="0.776470588235294 0.756862745098039 0.737254901960784 1" />
      </material>
    </visual>
    <collision>
      <origin
        xyz="0 0 0"
        rpy="0 0 0" />
      <geometry>
        <mesh
          filename="package://kanuopu-robot/meshes/WAIST_Y_S.STL" />
      </geometry>
    </collision>
  </link>
  <joint
    name="WAIST_Y"
    type="revolute">
    <origin
      xyz="0.0528 0 0.044"
      rpy="0 0 0" />
    <parent
      link="WAIST_R_S" />
    <child
      link="WAIST_Y_S" />
    <axis
      xyz="0 0 1" />
    <limit
      lower="-0.17453"
      upper="0.17453"
      effort="32"
      velocity="6.39" />
  </joint>
  <link
    name="WAIST_P_S">
    <inertial>
              <origin 
                xyz="-0.038325000000000005 -0.047687 0.15295599999999998" 
                rpy="0 0 0" />
              <mass 
                value="6.804443" />
              <inertia
                ixx="0.07040564890800001"
                ixy="-3.3659900999999995e-05"
                ixz="-0.013479768373999999"
                iyy="0.074505722415"
                iyz="-0.0010993000009999999"
                izz="0.03797654653" />
            </inertial>
    <visual>
      <origin
        xyz="0 0 0"
        rpy="0 0 0" />
      <geometry>
        <mesh
          filename="package://kanuopu-robot/meshes/WAIST_P_S.STL" />
      </geometry>
      <material
        name="">
        <color
          rgba="0.776470588235294 0.756862745098039 0.737254901960784 1" />
      </material>
    </visual>
    <collision>
      <origin
        xyz="0 0 0"
        rpy="0 0 0" />
      <geometry>
        <mesh
          filename="package://kanuopu-robot/meshes/WAIST_P_S.STL" />
      </geometry>
    </collision>
  </link>
  <joint
    name="WAIST_P"
    type="revolute">
    <origin
      xyz="0 0.0475 0.055"
      rpy="0 0 0" />
    <parent
      link="WAIST_Y_S" />
    <child
      link="WAIST_P_S" />
    <axis
      xyz="0 -1 0" />
    <limit
      lower="-0.5236"
      upper="0.5236"
      effort="32"
      velocity="6.39" />
  </joint>
  <link
    name="R_SHOULDER_P_S">
    <inertial>
              <origin 
                xyz="-0.000194 -0.056750999999999996 -2e-06" 
                rpy="0 0 0" />
              <mass 
                value="0.840858" />
              <inertia
                ixx="0.000523879592"
                ixy="-7.936799e-06"
                ixz="1.696e-09"
                iyy="0.000454438271"
                iyz="3.1817e-08"
                izz="0.00065628028" />
            </inertial>
    <visual>
      <origin
        xyz="0 0 0"
        rpy="0 0 0" />
      <geometry>
        <mesh
          filename="package://kanuopu-robot/meshes/R_SHOULDER_P_S.STL" />
      </geometry>
      <material
        name="">
        <color
          rgba="0.466666666666667 0.466666666666667 1 1" />
      </material>
    </visual>
    <collision>
      <origin
        xyz="0 0 0"
        rpy="0 0 0" />
      <geometry>
        <mesh
          filename="package://kanuopu-robot/meshes/R_SHOULDER_P_S.STL" />
      </geometry>
    </collision>
  </link>
  <joint
    name="R_SHOULDER_P"
    type="revolute">
    <origin
      xyz="0 -0.1655 0.257"
      rpy="0 0 0" />
    <parent
      link="WAIST_P_S" />
    <child
      link="R_SHOULDER_P_S" />
    <axis
      xyz="0 -1 0" />
    <limit
      lower="-3.1416"
      upper="3.1416"
      effort="30"
      velocity="3.56" />
  </joint>
  <link
    name="R_SHOULDER_R_S">
    <inertial>
              <origin 
                xyz="-0.030286 -0.096741 0.0" 
                rpy="0 0 0" />
              <mass 
                value="0.643146" />
              <inertia
                ixx="0.0012506429469999998"
                ixy="-8.4570409e-05"
                ixz="3.8e-10"
                iyy="0.00035315896399999995"
                iyz="8.309999999999999e-10"
                izz="0.0013891790319999998" />
            </inertial>
    <visual>
      <origin
        xyz="0 0 0"
        rpy="0 0 0" />
      <geometry>
        <mesh
          filename="package://kanuopu-robot/meshes/R_SHOULDER_R_S.STL" />
      </geometry>
      <material
        name="">
        <color
          rgba="0.890196078431372 0.890196078431372 0.913725490196078 1" />
      </material>
    </visual>
    <collision>
      <origin
        xyz="0 0 0"
        rpy="0 0 0" />
      <geometry>
        <mesh
          filename="package://kanuopu-robot/meshes/R_SHOULDER_R_S.STL" />
      </geometry>
    </collision>
  </link>
  <joint
    name="R_SHOULDER_R"
    type="revolute">
    <origin
      xyz="0.0315 -0.063 0"
      rpy="0 0 0" />
    <parent
      link="R_SHOULDER_P_S" />
    <child
      link="R_SHOULDER_R_S" />
    <axis
      xyz="1 0 0" />
    <limit
      lower="-0.5236"
      upper="1.5708"
      effort="30"
      velocity="3.56" />
  </joint>
  <link
    name="R_SHOULDER_Y_S">
    <inertial>
              <origin 
                xyz="0.0068 -0.08468600000000001 0.000104" 
                rpy="0 0 0" />
              <mass 
                value="0.5618179999999999" />
              <inertia
                ixx="0.000585250386"
                ixy="4.6500722e-05"
                ixz="1.945379e-06"
                iyy="0.000183615299"
                iyz="2.4762299999999997e-07"
                izz="0.000627811617" />
            </inertial>
    <visual>
      <origin
        xyz="0 0 0"
        rpy="0 0 0" />
      <geometry>
        <mesh
          filename="package://kanuopu-robot/meshes/R_SHOULDER_Y_S.STL" />
      </geometry>
      <material
        name="">
        <color
          rgba="0.890196078431372 0.890196078431372 0.913725490196078 1" />
      </material>
    </visual>
    <collision>
      <origin
        xyz="0 0 0"
        rpy="0 0 0" />
      <geometry>
        <mesh
          filename="package://kanuopu-robot/meshes/R_SHOULDER_Y_S.STL" />
      </geometry>
    </collision>
  </link>
  <joint
    name="R_SHOULDER_Y"
    type="revolute">
    <origin
      xyz="-0.0315 -0.1425 0"
      rpy="0 0 0" />
    <parent
      link="R_SHOULDER_R_S" />
    <child
      link="R_SHOULDER_Y_S" />
    <axis
      xyz="0 -1 0" />
    <limit
      lower="-3.1416"
      upper="3.1416"
      effort="9.6"
      velocity="3.87" />
  </joint>
  <link
    name="R_ELBOW_Y_S">
    <inertial>
              <origin 
                xyz="-0.027983 -0.071035 0.0" 
                rpy="0 0 0" />
              <mass 
                value="0.43879" />
              <inertia
                ixx="0.000454852451"
                ixy="-3.686286e-05"
                ixz="3.359e-09"
                iyy="0.000211160605"
                iyz="1.2435e-08"
                izz="0.000532377032" />
            </inertial>
    <visual>
      <origin
        xyz="0 0 0"
        rpy="0 0 0" />
      <geometry>
        <mesh
          filename="package://kanuopu-robot/meshes/R_ELBOW_Y_S.STL" />
      </geometry>
      <material
        name="">
        <color
          rgba="1 1 0.501960784313725 1" />
      </material>
    </visual>
    <collision>
      <origin
        xyz="0 0 0"
        rpy="0 0 0" />
      <geometry>
        <mesh
          filename="package://kanuopu-robot/meshes/R_ELBOW_Y_S.STL" />
      </geometry>
    </collision>
  </link>
  <joint
    name="R_ELBOW_Y"
    type="revolute">
    <origin
      xyz="0.0296 -0.0975 0"
      rpy="0 0 0" />
    <parent
      link="R_SHOULDER_Y_S" />
    <child
      link="R_ELBOW_Y_S" />
    <axis
      xyz="1 0 0" />
    <limit
      lower="0"
      upper="2.0071"
      effort="9.6"
      velocity="3.87" />
  </joint>
  <link
    name="R_WRIST_P_S">
    <inertial>
              <origin 
                xyz="4e-06 -0.049203000000000004 0.023254" 
                rpy="0 0 0" />
              <mass 
                value="0.394398" />
              <inertia
                ixx="0.000508578041"
                ixy="2.9748999999999997e-08"
                ixz="7.486799999999999e-08"
                iyy="0.00014304409899999998"
                iyz="9.0636944e-05"
                izz="0.000473947691" />
            </inertial>
    <visual>
      <origin
        xyz="0 0 0"
        rpy="0 0 0" />
      <geometry>
        <mesh
          filename="package://kanuopu-robot/meshes/R_WRIST_P_S.STL" />
      </geometry>
      <material
        name="">
        <color
          rgba="0.890196078431372 0.890196078431372 0.913725490196078 1" />
      </material>
    </visual>
    <collision>
      <origin
        xyz="0 0 0"
        rpy="0 0 0" />
      <geometry>
        <mesh
          filename="package://kanuopu-robot/meshes/R_WRIST_P_S.STL" />
      </geometry>
    </collision>
  </link>
  <joint
    name="R_WRIST_P"
    type="revolute">
    <origin
      xyz="-0.0296 -0.113 0"
      rpy="0 0 0" />
    <parent
      link="R_ELBOW_Y_S" />
    <child
      link="R_WRIST_P_S" />
    <axis
      xyz="0 -1 0" />
    <limit
      lower="-3.1416"
      upper="3.1416"
      effort="6.5"
      velocity="4.19" />
  </joint>
  <link
    name="R_WRIST_Y_S">
    <inertial>
              <origin 
                xyz="0.006343 -9.3e-05 -0.032466999999999996" 
                rpy="0 0 0" />
              <mass 
                value="0.25751" />
              <inertia
                ixx="6.712070200000001e-05"
                ixy="-8.07399e-07"
                ixz="1.376582e-06"
                iyy="8.8644898e-05"
                iyz="-1.09359e-07"
                izz="6.7677501e-05" />
            </inertial>
    <visual>
      <origin
        xyz="0 0 0"
        rpy="0 0 0" />
      <geometry>
        <mesh
          filename="package://kanuopu-robot/meshes/R_WRIST_Y_S.STL" />
      </geometry>
      <material
        name="">
        <color
          rgba="0.647058823529412 0.619607843137255 0.588235294117647 1" />
      </material>
    </visual>
    <collision>
      <origin
        xyz="0 0 0"
        rpy="0 0 0" />
      <geometry>
        <mesh
          filename="package://kanuopu-robot/meshes/R_WRIST_Y_S.STL" />
      </geometry>
    </collision>
  </link>
  <joint
    name="R_WRIST_Y"
    type="revolute">
    <origin
      xyz="0 -0.116 0.037"
      rpy="0 0 0" />
    <parent
      link="R_WRIST_P_S" />
    <child
      link="R_WRIST_Y_S" />
    <axis
      xyz="0 0 1" />
    <limit
      lower="-1.3963"
      upper="1.3963"
      effort="2.8"
      velocity="4.71" />
  </joint>
  <link
    name="R_WRIST_R_S">
    <inertial>
              <origin 
                xyz="-0.01907 -0.15728299999999998 -0.01332" 
                rpy="0 0 0" />
              <mass 
                value="0.77062" />
              <inertia
                ixx="0.003010840073"
                ixy="8.4372118e-05"
                ixz="-1.332972e-05"
                iyy="0.000364102783"
                iyz="0.000136549027"
                izz="0.00294791308" />
            </inertial>
    <visual>
      <origin
        xyz="0 0 0"
        rpy="0 0 0" />
      <geometry>
        <mesh
          filename="package://kanuopu-robot/meshes/R_WRIST_R_S.STL" />
      </geometry>
      <material
        name="">
        <color
          rgba="0.776470588235294 0.756862745098039 0.737254901960784 1" />
      </material>
    </visual>
    <collision>
      <origin
        xyz="0 0 0"
        rpy="0 0 0" />
      <geometry>
        <mesh
          filename="package://kanuopu-robot/meshes/R_WRIST_R_S.STL" />
      </geometry>
    </collision>
  </link>
  <joint
    name="R_WRIST_R"
    type="revolute">
    <origin
      xyz="0.026 0 -0.037"
      rpy="0 0 0" />
    <parent
      link="R_WRIST_Y_S" />
    <child
      link="R_WRIST_R_S" />
    <axis
      xyz="1 0 0" />
    <limit
      lower="0"
      upper="1.5533"
      effort="2.8"
      velocity="4.71" />
  </joint>
  <link
    name="L_SHOULDER_P_S">
    <inertial>
              <origin 
                xyz="-0.000194 0.056750999999999996 1e-06" 
                rpy="0 0 0" />
              <mass 
                value="0.840858" />
              <inertia
                ixx="0.000523875497"
                ixy="7.9463e-06"
                ixz="1.077e-08"
                iyy="0.000454438393"
                iyz="3.4536e-08"
                izz="0.000656276063" />
            </inertial>
    <visual>
      <origin
        xyz="0 0 0"
        rpy="0 0 0" />
      <geometry>
        <mesh
          filename="package://kanuopu-robot/meshes/L_SHOULDER_P_S.STL" />
      </geometry>
      <material
        name="">
        <color
          rgba="0.466666666666667 0.466666666666667 1 1" />
      </material>
    </visual>
    <collision>
      <origin
        xyz="0 0 0"
        rpy="0 0 0" />
      <geometry>
        <mesh
          filename="package://kanuopu-robot/meshes/L_SHOULDER_P_S.STL" />
      </geometry>
    </collision>
  </link>
  <joint
    name="L_SHOULDER_P"
    type="revolute">
    <origin
      xyz="0 0.0705 0.257"
      rpy="0 0 0" />
    <parent
      link="WAIST_P_S" />
    <child
      link="L_SHOULDER_P_S" />
    <axis
      xyz="0 1 0" />
    <limit
      lower="-3.1416"
      upper="3.1416"
      effort="30"
      velocity="3.56" />
  </joint>
  <link
    name="L_SHOUDLER_R_S">
    <inertial>
              <origin 
                xyz="-0.030284 0.096741 0.0" 
                rpy="0 0 0" />
              <mass 
                value="0.643146" />
              <inertia
                ixx="0.001250643438"
                ixy="8.469165e-05"
                ixz="-3.82e-10"
                iyy="0.000353007409"
                iyz="8.259999999999999e-10"
                izz="0.0013890279680000002" />
            </inertial>
    <visual>
      <origin
        xyz="0 0 0"
        rpy="0 0 0" />
      <geometry>
        <mesh
          filename="package://kanuopu-robot/meshes/L_SHOUDLER_R_S.STL" />
      </geometry>
      <material
        name="">
        <color
          rgba="0.890196078431372 0.890196078431372 0.913725490196078 1" />
      </material>
    </visual>
    <collision>
      <origin
        xyz="0 0 0"
        rpy="0 0 0" />
      <geometry>
        <mesh
          filename="package://kanuopu-robot/meshes/L_SHOUDLER_R_S.STL" />
      </geometry>
    </collision>
  </link>
  <joint
    name="L_SHOUDLER_R"
    type="revolute">
    <origin
      xyz="0.0315 0.063 0"
      rpy="0 0 0" />
    <parent
      link="L_SHOULDER_P_S" />
    <child
      link="L_SHOUDLER_R_S" />
    <axis
      xyz="1 0 0" />
    <limit
      lower="-1.5708"
      upper="0.5236"
      effort="30"
      velocity="3.56" />
  </joint>
  <link
    name="L_SHOULDER_Y_S">
    <inertial>
              <origin 
                xyz="0.0068 0.084941 0.000104" 
                rpy="0 0 0" />
              <mass 
                value="0.5618179999999999" />
              <inertia
                ixx="0.000588890782"
                ixy="-4.1531607000000007e-05"
                ixz="1.945227e-06"
                iyy="0.00018361529500000002"
                iyz="-1.229557e-06"
                izz="0.000631452018" />
            </inertial>
    <visual>
      <origin
        xyz="0 0 0"
        rpy="0 0 0" />
      <geometry>
        <mesh
          filename="package://kanuopu-robot/meshes/L_SHOULDER_Y_S.STL" />
      </geometry>
      <material
        name="">
        <color
          rgba="0.890196078431372 0.890196078431372 0.913725490196078 1" />
      </material>
    </visual>
    <collision>
      <origin
        xyz="0 0 0"
        rpy="0 0 0" />
      <geometry>
        <mesh
          filename="package://kanuopu-robot/meshes/L_SHOULDER_Y_S.STL" />
      </geometry>
    </collision>
  </link>
  <joint
    name="L_SHOULDER_Y"
    type="revolute">
    <origin
      xyz="-0.0315 0.1425 0"
      rpy="0 0 0" />
    <parent
      link="L_SHOUDLER_R_S" />
    <child
      link="L_SHOULDER_Y_S" />
    <axis
      xyz="0 1 0" />
    <limit
      lower="-3.1416"
      upper="3.1416"
      effort="9.6"
      velocity="3.87" />
  </joint>
  <link
    name="L_ELBOW_Y_S">
    <inertial>
              <origin 
                xyz="-0.027983 0.071035 0.0" 
                rpy="0 0 0" />
              <mass 
                value="0.43879" />
              <inertia
                ixx="0.000454852875"
                ixy="3.6862731e-05"
                ixz="-3.3610000000000003e-09"
                iyy="0.000211160605"
                iyz="1.2432e-08"
                izz="0.000532377457" />
            </inertial>
    <visual>
      <origin
        xyz="0 0 0"
        rpy="0 0 0" />
      <geometry>
        <mesh
          filename="package://kanuopu-robot/meshes/L_ELBOW_Y_S.STL" />
      </geometry>
      <material
        name="">
        <color
          rgba="1 1 0.501960784313725 1" />
      </material>
    </visual>
    <collision>
      <origin
        xyz="0 0 0"
        rpy="0 0 0" />
      <geometry>
        <mesh
          filename="package://kanuopu-robot/meshes/L_ELBOW_Y_S.STL" />
      </geometry>
    </collision>
  </link>
  <joint
    name="L_ELBOW_Y"
    type="revolute">
    <origin
      xyz="0.0296 0.0975 0"
      rpy="0 0 0" />
    <parent
      link="L_SHOULDER_Y_S" />
    <child
      link="L_ELBOW_Y_S" />
    <axis
      xyz="1 0 0" />
    <limit
      lower="-2.0071"
      upper="0"
      effort="9.6"
      velocity="3.87" />
  </joint>
  <link
    name="L_WRIST_P_S">
    <inertial>
              <origin 
                xyz="4e-06 0.049033 0.023283" 
                rpy="0 0 0" />
              <mass 
                value="0.394398" />
              <inertia
                ixx="0.000510315583"
                ixy="6.3957e-08"
                ixz="8.0429e-08"
                iyy="0.000143357897"
                iyz="-9.399042e-05"
                izz="0.000475371436" />
            </inertial>
    <visual>
      <origin
        xyz="0 0 0"
        rpy="0 0 0" />
      <geometry>
        <mesh
          filename="package://kanuopu-robot/meshes/L_WRIST_P_S.STL" />
      </geometry>
      <material
        name="">
        <color
          rgba="0.890196078431372 0.890196078431372 0.913725490196078 1" />
      </material>
    </visual>
    <collision>
      <origin
        xyz="0 0 0"
        rpy="0 0 0" />
      <geometry>
        <mesh
          filename="package://kanuopu-robot/meshes/L_WRIST_P_S.STL" />
      </geometry>
    </collision>
  </link>
  <joint
    name="L_WRIST_P"
    type="revolute">
    <origin
      xyz="-0.0296 0.113 0"
      rpy="0 0 0" />
    <parent
      link="L_ELBOW_Y_S" />
    <child
      link="L_WRIST_P_S" />
    <axis
      xyz="0 1 0" />
    <limit
      lower="-3.1416"
      upper="3.1416"
      effort="6.5"
      velocity="4.19" />
  </joint>
  <link
    name="L_WRIST_Y_S">
    <inertial>
              <origin 
                xyz="0.006343 -0.000118 -0.032517000000000004" 
                rpy="0 0 0" />
              <mass 
                value="0.25751" />
              <inertia
                ixx="6.7234341e-05"
                ixy="-1.0177709999999999e-06"
                ixz="9.48621e-07"
                iyy="8.8778895e-05"
                iyz="-1.73977e-07"
                izz="6.765714299999999e-05" />
            </inertial>
    <visual>
      <origin
        xyz="0 0 0"
        rpy="0 0 0" />
      <geometry>
        <mesh
          filename="package://kanuopu-robot/meshes/L_WRIST_Y_S.STL" />
      </geometry>
      <material
        name="">
        <color
          rgba="0.647058823529412 0.619607843137255 0.588235294117647 1" />
      </material>
    </visual>
    <collision>
      <origin
        xyz="0 0 0"
        rpy="0 0 0" />
      <geometry>
        <mesh
          filename="package://kanuopu-robot/meshes/L_WRIST_Y_S.STL" />
      </geometry>
    </collision>
  </link>
  <joint
    name="L_WRIST_Y"
    type="revolute">
    <origin
      xyz="0 0.116 0.037"
      rpy="0 0 0" />
    <parent
      link="L_WRIST_P_S" />
    <child
      link="L_WRIST_Y_S" />
    <axis
      xyz="0 0 1" />
    <limit
      lower="-1.3963"
      upper="1.3963"
      effort="2.8"
      velocity="4.71" />
  </joint>
  <link
    name="L_WRIST_R_S">
    <inertial>
              <origin 
                xyz="-0.021523 0.14997300000000002 -0.013839" 
                rpy="0 0 0" />
              <mass 
                value="0.77062" />
              <inertia
                ixx="0.00268767041"
                ixy="-1.4053498e-05"
                ixz="-3.83745e-07"
                iyy="0.00036157641"
                iyz="-9.7179766e-05"
                izz="0.0026076142030000003" />
            </inertial>
    <visual>
      <origin
        xyz="0 0 0"
        rpy="0 0 0" />
      <geometry>
        <mesh
          filename="package://kanuopu-robot/meshes/L_WRIST_R_S.STL" />
      </geometry>
      <material
        name="">
        <color
          rgba="0.776470588235294 0.756862745098039 0.737254901960784 1" />
      </material>
    </visual>
    <collision>
      <origin
        xyz="0 0 0"
        rpy="0 0 0" />
      <geometry>
        <mesh
          filename="package://kanuopu-robot/meshes/L_WRIST_R_S.STL" />
      </geometry>
    </collision>
  </link>
  <joint
    name="L_WRIST_R"
    type="revolute">
    <origin
      xyz="0.026 0 -0.037"
      rpy="0 0 0" />
    <parent
      link="L_WRIST_Y_S" />
    <child
      link="L_WRIST_R_S" />
    <axis
      xyz="1 0 0" />
    <limit
      lower="-1.5533"
      upper="0.08727"
      effort="2.8"
      velocity="4.71" />
  </joint>
  <link
    name="NECK_Y_S">
    <inertial>
              <origin 
                xyz="-0.003437 -0.032159 0.043421999999999995" 
                rpy="0 0 0" />
              <mass 
                value="0.373532" />
              <inertia
                ixx="0.000349489996"
                ixy="-5.305669e-06"
                ixz="-1.0882511e-05"
                iyy="0.00033792047200000003"
                iyz="5.6085116e-05"
                izz="9.3684199e-05" />
            </inertial>
    <visual>
      <origin
        xyz="0 0 0"
        rpy="0 0 0" />
      <geometry>
        <mesh
          filename="package://kanuopu-robot/meshes/NECK_Y_S.STL" />
      </geometry>
      <material
        name="">
        <color
          rgba="0.866666666666667 0.866666666666667 0.890196078431372 1" />
      </material>
    </visual>
    <collision>
      <origin
        xyz="0 0 0"
        rpy="0 0 0" />
      <geometry>
        <mesh
          filename="package://kanuopu-robot/meshes/NECK_Y_S.STL" />
      </geometry>
    </collision>
  </link>
  <joint
    name="NECK_Y"
    type="revolute">
    <origin
      xyz="0 -0.0475 0.299"
      rpy="0 0 0" />
    <parent
      link="WAIST_P_S" />
    <child
      link="NECK_Y_S" />
    <axis
      xyz="0 0 1" />
    <limit
      lower="-1.5708"
      upper="1.5708"
      effort="6.5"
      velocity="4.19" />
  </joint>
  <link
    name="NECK_P_S">
    <inertial>
              <origin 
                xyz="0.02161 0.028097 -0.002907" 
                rpy="0 0 0" />
              <mass 
                value="0.244094" />
              <inertia
                ixx="2.4512597e-05"
                ixy="-1.3057729e-05"
                ixz="2.618482e-06"
                iyy="2.4448557e-05"
                iyz="1.85446e-06"
                izz="3.5449779e-05" />
            </inertial>
    <visual>
      <origin
        xyz="0 0 0"
        rpy="0 0 0" />
      <geometry>
        <mesh
          filename="package://kanuopu-robot/meshes/NECK_P_S.STL" />
      </geometry>
      <material
        name="">
        <color
          rgba="0.647058823529412 0.619607843137255 0.588235294117647 1" />
      </material>
    </visual>
    <collision>
      <origin
        xyz="0 0 0"
        rpy="0 0 0" />
      <geometry>
        <mesh
          filename="package://kanuopu-robot/meshes/NECK_P_S.STL" />
      </geometry>
    </collision>
  </link>
  <joint
    name="NECK_P"
    type="revolute">
    <origin
      xyz="0 -0.037 0.102"
      rpy="0 0 0" />
    <parent
      link="NECK_Y_S" />
    <child
      link="NECK_P_S" />
    <axis
      xyz="0 -1 0" />
    <limit
      lower="-0.5236"
      upper="0.69813"
      effort="2.8"
      velocity="4.71" />
  </joint>
  <link
    name="NECK_R_S">
    <inertial>
              <origin 
                xyz="0.025114 -1e-06 0.100658" 
                rpy="0 0 0" />
              <mass 
                value="0.384063" />
              <inertia
                ixx="0.000454388505"
                ixy="9.1984e-08"
                ixz="7.5724749e-05"
                iyy="0.001102873495"
                iyz="6.7270000000000004e-09"
                izz="0.000944836581" />
            </inertial>
    <visual>
      <origin
        xyz="0 0 0"
        rpy="0 0 0" />
      <geometry>
        <mesh
          filename="package://kanuopu-robot/meshes/NECK_R_S.STL" />
      </geometry>
      <material
        name="">
        <color
          rgba="0.776470588235294 0.756862745098039 0.737254901960784 1" />
      </material>
    </visual>
    <collision>
      <origin
        xyz="0 0 0"
        rpy="0 0 0" />
      <geometry>
        <mesh
          filename="package://kanuopu-robot/meshes/NECK_R_S.STL" />
      </geometry>
    </collision>
  </link>
  <joint
    name="NECK_R"
    type="revolute">
    <origin
      xyz="0.026 0.037 0"
      rpy="0 0 0" />
    <parent
      link="NECK_P_S" />
    <child
      link="NECK_R_S" />
    <axis
      xyz="1 0 0" />
    <limit
      lower="-0.2618"
      upper="0.2618"
      effort="2.8"
      velocity="4.71" />
  </joint>
</robot>
